<?xml version="1.0" encoding="UTF-8"?>

<robot name="goal" xmlns:xacro="http://www.ros.org/wiki/xacro">
    <xacro:include filename="$(find my_robot_description)/urdf/links_joints.xacro"/>

    <xacro:m_link_wall name="base" origin_rpy="1.57 0 0 " origin_xyz="-0.5 0 -0.5" mass="100" ixx="0.0"
                       ixy="0" ixz="0" iyy="0.0" iyz="0" izz="0.0"/>
    <xacro:m_link_button name="button" origin_rpy="0 0 0" origin_xyz="0.0 0.0 0.0" size="0.1 0.02 0.1" mass="0.1"
                         ixx="0.1" ixy="0" ixz="0" iyy="0.1" iyz="0" izz="0.1"/>

    <joint name="wall_button" type="prismatic">
        <parent link="base"/>
        <child link="button"/>
        <origin xyz="0 0 0" rpy="0 0 0"/>
        <axis xyz="0 1 0"/>
        <limit effort="10" lower="0.0" upper="0.5" velocity="1"/>
    </joint>

    <transmission name="wall_button_trans">
        <type>transmission_interface/SimpleTransmission</type>
        <joint name="wall_button">
            <hardwareInterface>hardware_interface/EffortJointInterface</hardwareInterface>
        </joint>
        <actuator name="motor_wall_button">
            <hardwareInterface>hardware_interface/EffortJointInterface</hardwareInterface>
            <mechanicalReduction>1</mechanicalReduction>
        </actuator>
    </transmission>


    <gazebo>
        <plugin name="gazebo_ros_control" filename="libgazebo_ros_control.so">
        </plugin>
    </gazebo>

    <gazebo reference="base">
        <gravity>0</gravity>
    </gazebo>

    <gazebo reference="button">
        <gravity>0</gravity>
    </gazebo>
</robot>

